Workbook

Sheet Sales target
A1: Month of Order Date | B1: Category | C1: Target | D1: MoM % Change
A2: 46041 | B2: Furniture | C2: 11500
A3: 46072 | B3: Furniture | C3: 11600 | D3: =(C3-C2)/C2 -> 0.0086956522
A4: 46100 | B4: Furniture | C4: 11800 | D4: =(C4-C3)/C3 -> 0.017241379
A5: 46130 | B5: Furniture | C5: 10400 | D5: =(C5-C4)/C4 -> -0.11864407
A6: 46160 | B6: Furniture | C6: 10500 | D6: =(C6-C5)/C5 -> 0.0096153846
A7: 46191 | B7: Furniture | C7: 10600 | D7: =(C7-C6)/C6 -> 0.0095238095
A8: 46221 | B8: Furniture | C8: 10800 | D8: =(C8-C7)/C7 -> 0.018867925
A9: 46252 | B9: Furniture | C9: 10900 | D9: =(C9-C8)/C8 -> 0.0092592593
A10: 46283 | B10: Furniture | C10: 11000 | D10: =(C10-C9)/C9 -> 0.0091743119
A11: 46313 | B11: Furniture | C11: 11100 | D11: =(C11-C10)/C10 -> 0.0090909091
A12: 46344 | B12: Furniture | C12: 11300 | D12: =(C12-C11)/C11 -> 0.018018018
A13: 46374 | B13: Furniture | C13: 11400 | D13: =(C13-C12)/C12 -> 0.0088495575
A14: 46130 | B14: Clothing | C14: 12000
A15: 46160 | B15: Clothing | C15: 12000
A16: 46191 | B16: Clothing | C16: 12000
A17: 46221 | B17: Clothing | C17: 14000
A18: 46252 | B18: Clothing | C18: 14000
A19: 46283 | B19: Clothing | C19: 14000
A20: 46313 | B20: Clothing | C20: 16000
A21: 46344 | B21: Clothing | C21: 16000
A22: 46374 | B22: Clothing | C22: 16000
A23: 46041 | B23: Clothing | C23: 16000
A24: 46072 | B24: Clothing | C24: 16000
A25: 46100 | B25: Clothing | C25: 16000
... A37: 46100 | B37: Electronics | C37: 16000

Sheet List of Orders
A1: Order ID | B1: Order Date | C1: CustomerName | D1: State | E1: City
A2: B-25601 | B2: 43104 | C2: Bharat | D2: Gujarat | E2: Ahmedabad
A3: B-25602 | B3: 43104 | C3: Pearl | D3: Maharashtra | E3: Pune
A4: B-25603 | B4: 43163 | C4: Jahan | D4: Madhya Pradesh | E4: Bhopal
A5: B-25604 | B5: 43163 | C5: Divsha | D5: Rajasthan | E5: Jaipur
A6: B-25605 | B6: 43224 | C6: Kasheen | D6: West Bengal | E6: Kolkata
A7: B-25606 | B7: 43255 | C7: Hazel | D7: Karnataka | E7: Bangalore
A8: B-25607 | B8: 43255 | C8: Sonakshi | D8: Jammu and Kashmir | E8: Kashmir
A9: B-25608 | B9: 43316 | C9: Aarushi | D9: Tamil Nadu | E9: Chennai
A10: B-25609 | B10: 43347 | C10: Jitesh | D10: Uttar Pradesh | E10: Lucknow
A11: B-25610 | B11: 43347 | C11: Yogesh | D11: Bihar | E11: Patna
A12: B-25611 | B12: 43408 | C12: Anita | D12: Kerala | E12: Thiruvananthapuram
A13: B-25612 | B13: 43438 | C13: Shrichand | D13: Punjab | E13: Chandigarh
A14: B-25613 | B14: 43438 | C14: Mukesh | D14: Haryana | E14: Chandigarh
A15: B-25614 | B15: 13-04-2018 | C15: Vandana | D15: Himachal Pradesh | E15: Simla
A16: B-25615 | B16: 15-04-2018 | C16: Bhavna | D16: Sikkim | E16: Gangtok
A17: B-25616 | B17: 15-04-2018 | C17: Kanak | D17: Goa | E17: Goa
A18: B-25617 | B18: 17-04-2018 | C18: Sagar | D18: Nagaland | E18: Kohima
A19: B-25618 | B19: 18-04-2018 | C19: Manju | D19: Andhra Pradesh | E19: Hyderabad
A20: B-25619 | B20: 18-04-2018 | C20: Ramesh | D20: Gujarat | E20: Ahmedabad
A21: B-25620 | B21: 20-04-2018 | C21: Sarita | D21: Maharashtra | E21: Pune
A22: B-25621 | B22: 20-04-2018 | C22: Deepak | D22: Madhya Pradesh | E22: Bhopal
A23: B-25622 | B23: 22-04-2018 | C23: Monisha | D23: Rajasthan | E23: Jaipur
A24: B-25623 | B24: 22-04-2018 | C24: Atharv | D24: West Bengal | E24: Kolkata
A25: B-25624 | B25: 22-04-2018 | C25: Vini | D25: Karnataka | E25: Bangalore
A26: B-25625 | B26: 23-04-2018 | C26: Pinky | D26: Jammu and Kashmir | E26: Kashmir
... A45: B-25644 | B45: 30-04-2018 | C45: Mayank | D45: Maharashtra | E45: Mumbai
A46: B-25645 | B46: 43105 | C46: Yaanvi | D46: Madhya Pradesh | E46: Indore
A47: B-25646 | B47: 43105 | C47: Sonal | D47: Bihar | E47: Patna
A48: B-25647 | B48: 43164 | C48: Sharda | D48: Kerala | E48: Thiruvananthapuram
A49: B-25648 | B49: 43195 | C49: Aditya | D49: Punjab | E49: Chandigarh
A50: B-25649 | B50: 43225 | C50: Rachna | D50: Haryana | E50: Chandigarh
A51: B-25650 | B51: 43256 | C51: Chirag | D51: Maharashtra | E51: Mumbai
A52: B-25651 | B52: 43286 | C52: Anurag | D52: Madhya Pradesh | E52: Indore
A53: B-25652 | B53: 43317 | C53: Tushina | D53: Goa | E53: Goa
A54: B-25653 | B54: 43317 | C54: Farah | D54: Nagaland | E54: Kohima
A55: B-25654 | B55: 43378 | C55: Sabah | D55: Maharashtra | E55: Mumbai
A56: B-25655 | B56: 43409 | C56: Nida | D56: Madhya Pradesh | E56: Indore
A57: B-25656 | B57: 43409 | C57: Priyanka | D57: Maharashtra | E57: Pune
A58: B-25657 | B58: 13-05-2018 | C58: Tulika | D58: Madhya Pradesh | E58: Bhopal
...

Sheet Order Details
A1: Order ID | B1: Amount | C1: Profit | D1: Quantity | E1: Category | F1: Sub-Category | G1: state
A2: B-25601 | B2: 1275 | C2: -1148 | D2: 7 | E2: Furniture | F2: Bookcases | G2: =VLOOKUP(A2, 'List of Orders'!A:E, 4, FALSE) -> Gujarat
A3: B-25601 | B3: 66 | C3: -12 | D3: 5 | E3: Clothing | F3: Stole | G3: =VLOOKUP(A3, 'List of Orders'!A:E, 4, FALSE) -> Gujarat
A4: B-25601 | B4: 8 | C4: -2 | D4: 3 | E4: Clothing | F4: Hankerchief | G4: =VLOOKUP(A4, 'List of Orders'!A:E, 4, FALSE) -> Gujarat
A5: B-25601 | B5: 80 | C5: -56 | D5: 4 | E5: Electronics | F5: Electronic Games | G5: =VLOOKUP(A5, 'List of Orders'!A:E, 4, FALSE) -> Gujarat
A6: B-25602 | B6: 168 | C6: -111 | D6: 2 | E6: Electronics | F6: Phones | G6: =VLOOKUP(A6, 'List of Orders'!A:E, 4, FALSE) -> Maharashtra
A7: B-25602 | B7: 424 | C7: -272 | D7: 5 | E7: Electronics | F7: Phones | G7: =VLOOKUP(A7, 'List of Orders'!A:E, 4, FALSE) -> Maharashtra
A8: B-25602 | B8: 2617 | C8: 1151 | D8: 4 | E8: Electronics | F8: Phones | G8: =VLOOKUP(A8, 'List of Orders'!A:E, 4, FALSE) -> Maharashtra
A9: B-25602 | B9: 561 | C9: 212 | D9: 3 | E9: Clothing | F9: Saree | G9: =VLOOKUP(A9, 'List of Orders'!A:E, 4, FALSE) -> Maharashtra
A10: B-25602 | B10: 119 | C10: -5 | D10: 8 | E10: Clothing | F10: Saree | G10: =VLOOKUP(A10, 'List of Orders'!A:E, 4, FALSE) -> Maharashtra
A11: B-25603 | B11: 1355 | C11: -60 | D11: 5 | E11: Clothing | F11: Trousers | G11: =VLOOKUP(A11, 'List of Orders'!A:E, 4, FALSE) -> Madhya Pradesh
A12: B-25603 | B12: 24 | C12: -30 | D12: 1 | E12: Furniture | F12: Chairs | G12: =VLOOKUP(A12, 'List of Orders'!A:E, 4, FALSE) -> Madhya Pradesh
A13: B-25603 | B13: 193 | C13: -166 | D13: 3 | E13: Clothing | F13: Saree | G13: =VLOOKUP(A13, 'List of Orders'!A:E, 4, FALSE) -> Madhya Pradesh
... A1501: B-26100 | B1501: 72 | C1501: 16 | D1501: 2 | E1501: Clothing | F1501: Shirt | G1501: =VLOOKUP(A1501, 'List of Orders'!A:E, 4, FALSE) -> Madhya Pradesh

Sheet Pivot Table 1
A1: Category | B1: SUM of Amount | C1: SUM of Profit | D1: COUNTUNIQUE of Order ID | E1: Profit Margin | F1: Avg Profit per Order
A2: Clothing | B2: 139054 | C2: 11163 | D2: 393 | E2: 0.080278165 | F2: =C2/D2 -> 28.40458
A3: Electronics | B3: 165267 | C3: 10494 | D3: 204 | E3: 0.06349725 | F3: =C3/D3 -> 51.441176
A4: Furniture | B4: 127181 | C4: 2298 | D4: 186 | E4: 0.018068737 | F4: =C4/D4 -> 12.354839
A5: Grand Total | B5: 431502 | C5: 23955 | D5: 500 | E5: 0.055515386

Sheet Pivot Table 2
A1: state | B1: Order Count | C1: Total Sales | D1: Total Profit | E1: Average Profit
A2: Madhya Pradesh | B2: 101 | C2: 105140 | D2: 5551 | E2: =D2/B2 -> 54.960396
A3: Maharashtra | B3: 90 | C3: 95348 | D3: 6176 | E3: =D3/B3 -> 68.622222
A4: Rajasthan | B4: 32 | C4: 21149 | D4: 1257 | E4: =D4/B4 -> 39.28125
A5: Gujarat | B5: 27 | C5: 21058 | D5: 465 | E5: =D5/B5 -> 17.222222
A6: Punjab | B6: 25 | C6: 16786 | D6: -609 | E6: =D6/B6 -> -24.36
A7: West Bengal | B7: 22 | C7: 14086 | D7: 2500 | E7: =D7/B7 -> 113.63636
A8: Uttar Pradesh | B8: 22 | C8: 22359 | D8: 3237 | E8: =D8/B8 -> 147.13636
A9: Delhi | B9: 22 | C9: 22531 | D9: 2987 | E9: =D9/B9 -> 135.77273
A10: Karnataka | B10: 21 | C10: 15058 | D10: 645 | E10: =D10/B10 -> 30.714286
A11: Kerala | B11: 16 | C11: 13459 | D11: 1871 | E11: =D11/B11 -> 116.9375
A12: Bihar | B12: 16 | C12: 12943 | D12: -321 | E12: =D12/B12 -> -20.0625
A13: Nagaland | B13: 15 | C13: 11903 | D13: 148 | E13: =D13/B13 -> 9.8666667
... A21: Grand Total | B21: 500 | C21: 431502 | D21: 23955 | E21: =D21/B21 -> 47.91
